Workbook

Sheet SEMANA 1
D1: LISTA DE CHEQUEO PARA PLAN DE MANEJO AMBIENTAL | K1: Código: GES-FO-082 Versión: 2 Fecha de Aprobación: 15-jun-2022 Clasificación: Público
B5: CONTRATO | C5: 703 del 2024 | E5: PROYECTO | F5: Parques y EP002 | H5: FASE O ETAPA | I5: 2 | K5: No. FASE / ETAPA: | L5: Obra
A8: PERIODO COMPRENDIDO ENTRE EL: | E8: 46027 | G8: Y EL | I8: 46000
A10: INFORME No. | D10: 7
A11: TIPO DE CONTRATO | D11: Obra
A12: OBJETO | D12: LA INTERVENTORÍA INTEGRAL (TÉCNICA, ADMINISTRATIVA, FINANCIERA, CONTABLE, LEGAL, AMBIENTAL Y DE SEGURIDAD Y SALUD EN EL TRABAJO) PARA REALIZAR LAS OBRAS DE CONSERVACIÓN Y CONSTRUCCIÓN DE: ESPACIO PUBLICO, PARQUES, PUENTES VEHICULARES Y/O PEATONALES SOBRE CUERPOS DE AGUA Y DE MALLA VIAL EN LA LOCALIDAD DE BOSA
A13: NOMBRE DEL PROYECTO | D13: Parques y EP002
A14: CONTRATISTA: | D14: CONSORCIO PARQUES Y EP002 | J14: CONTRATO No: | L14: 703 del 2024
A15: INTERVENTOR: | D15: CONSORCIO INFRAESTRUCTURA BOSA | J15: CONTRATO No: | L15: FDT-ATBOSA-I-028-2025
A16: SUPERVISOR: | D16: Dario Morales
A17: FECHA: | D17: 46053
N18: Porcentaje total de componentes 100% | O18: %Cump | P18: %Cumpli. | Q18: %Cumpli. | R18: %Cumpli. | S18: %Cumpli. | T18: %Cumpli.
A19: No. | B19: DESCRIPCIÓN | J19: SI | K19: NO | L19: N.A. | M19: RESUELTO | N19: PONDERACION | O19: 46027 | P19: 46028 | Q19: 46029 | R19: 46030 | S19: 46031 | T19: PROMEDIO | U19: Componente%
A20: COMPONENTE A | U20: 20 | AC20: Aplicabilidad | AD20: Ponderación
A21: 1 | B21: El contratista mantiene actualizado el contenido de las carpetas A&SST exigidas | J21: X | N21: 4 | O21: 0 | P21: 0 | Q21: 0 | R21: 1 | S21: 1 | T21: =AVERAGE(O21:S21) -> 0.4 | U21: =IF(SUM(N21:N25)<>U20,"Ajustar Ponderacion",IF(SUM(AD21:AD25)=0,"",IF(SUM(AC21:AC25)=U20,IF(SUM(N21:N25)=U20,SUM(AD21:AD25),"Ajustar ponderacion"),"Ajustar ponderacion"))) -> 17.6 | AC21: =IF(J21="x",N21) -> 4 | AD21: =AC21*T21 -> 1.6 | AF21: 0
A22: 2 | B22: Se cumple con el plan de acciones correctivas y/o preventivas a las observaciones en el ámbito A&SST hechas por la Interventoría en el desarrollo de las actividades del proyecto | J22: X | N22: 4 | O22: 1 | P22: 1 | Q22: 1 | R22: 1 | S22: 1 | T22: =AVERAGE(O22:S22) -> 1 | AC22: =IF(J22="x",N22) -> 4 | AD22: =AC22*T22 -> 4 | AF22: 100
A23: 3 | B23: La brigada de orden, aseo y limpieza – BOAL está conformada y dotada de acuerdo a lo especificado en el pliego de condiciones y cumple sus funciones. | J23: X | N23: 4 | O23: 1 | P23: 1 | Q23: 1 | R23: 1 | S23: 1 | T23: =AVERAGE(O23:S23) -> 1 | AC23: =IF(J23="x",N23) -> 4 | AD23: =AC23*T23 -> 4
A24: 4 | B24: Se entrega de manera oportuna de acuerdo a lo definido en los comités, todos los soportes de proveedores de materiales y sitio de disposición final de RCD producto de las actividades de obra. | J24: X | N24: 4 | O24: 1 | P24: 1 | Q24: 1 | R24: 1 | S24: 1 | T24: =AVERAGE(O24:S24) -> 1 | AC24: =IF(J24="x",N24) -> 4 | AD24: =AC24*T24 -> 4
A25: 5 | B25: Se cumple con todos los procedimientos ofertados en el MAO aprobado | J25: X | N25: 4 | O25: 1 | P25: 1 | Q25: 1 | R25: 1 | S25: 1 | T25: =AVERAGE(O25:S25) -> 1 | AC25: =IF(J25="x",N25) -> 4 | AD25: =AC25*T25 -> 4
A26: COMPONENTE B | U26: 50 | AC26: =IF(J26="x",N26) -> FALSE | AD26: =AC26*T26 -> 0
A27: 6 | B27: Hay escombros o materiales en espacio publico | J27: X | N27: 2.5 | O27: 1 | P27: 1 | Q27: 1 | R27: 1 | S27: 1 | T27: =AVERAGE(O27:S27) -> 1 | U27: =IF(SUM(N27:N46)<>U26,"Ajuste ponderacion",IF(SUM(AD27:AD46)=0,"",IF(SUM(AC27:AC46)=U26,IF(SUM(N27:N46)=U26,SUM(AD27:AD46),"ajustar ponderacion"),"ajustar ponderacion"))) -> 50 | AC27: =IF(J27="x",N27) -> 2.5 | AD27: =AC27*T27 -> 2.5
A28: 7 | B28: Los materiales de la obra están cubiertos con lonas, plásticos o geotextil y acordonados | J28: X | N28: 2.5 | O28: 1 | P28: 1 | Q28: 1 | R28: 1 | S28: 1 | T28: =AVERAGE(O28:S28) -> 1 | AC28: =IF(J28="x",N28) -> 2.5 | AD28: =AC28*T28 -> 2.5
A29: 8 | B29: Se implementan las medidas de manejo necesarias para impedir el aporte de sólidos o sustancias contaminantes al sistema de alcantarillado o cuerpos de agua. | J29: X | N29: 2.5 | O29: 1 | P29: 1 | Q29: 1 | R29: 1 | S29: 1 | T29: =AVERAGE(O29:S29) -> 1 | AC29: =IF(J29="x",N29) -> 2.5 | AD29: =AC29*T29 -> 2.5
A30: 9 | B30: El campamento de obra se encuentra debidamente demarcado, señalizado, ordenado y aseado de acuerdo a lo ofertado en el MAO. | J30: X | N30: 2.5 | O30: 1 | P30: 1 | Q30: 1 | R30: 1 | S30: 1 | T30: =AVERAGE(O30:S30) -> 1 | AC30: =IF(J30="x",N30) -> 2.5 | AD30: =AC30*T30 -> 2.5
A31: 10 | B31: Existe aislamiento del equipo y operario en uso de cortadora, para mitigar el material particulado | J31: X | N31: 2.5 | O31: 1 | P31: 1 | Q31: 1 | R31: 1 | S31: 1 | T31: =AVERAGE(O31:S31) -> 1 | AC31: =IF(J31="x",N31) -> 2.5 | AD31: =AC31*T31 -> 2.5
A32: 11 | B32: Los materiales almacenados interfieren el trafico peatonal, vehicular y espacio publico | J32: X | N32: 2.5 | O32: 1 | P32: 1 | Q32: 1 | R32: 1 | S32: 1 | T32: =AVERAGE(O32:S32) -> 1 | AC32: =IF(J32="x",N32) -> 2.5 | AD32: =AC32*T32 -> 2.5
A33: 12 | B33: Los vehículos para transporte de material no exceden su capacidad, están cubiertos los escombros | J33: X | N33: 2.5 | O33: 1 | P33: 1 | Q33: 1 | R33: 1 | S33: 1 | T33: =AVERAGE(O33:S33) -> 1 | AC33: =IF(J33="x",N33) -> 2.5 | AD33: =AC33*T33 -> 2.5
A34: 13 | B34: Se garantiza la limpieza de las llantas de todos los vehículos que salen de la obra | J34: X | N34: 2.5 | O34: 1 | P34: 1 | Q34: 1 | R34: 1 | S34: 1 | T34: =AVERAGE(O34:S34) -> 1 | AC34: =IF(J34="x",N34) -> 2.5 | AD34: =AC34*T34 -> 2.5
A35: 14 | B35: Se limpia el lugar donde se cargan las volquetas | J35: X | N35: 2.5 | O35: 1 | P35: 1 | Q35: 1 | R35: 1 | S35: 1 | T35: =AVERAGE(O35:S35) -> 1 | AC35: =IF(J35="x",N35) -> 2.5 | AD35: =AC35*T35 -> 2.5
A36: 15 | B36: Se realiza la disposición final de los escombros en lugar autorizado | J36: X | N36: 2.5 | O36: 1 | P36: 1 | Q36: 1 | R36: 1 | S36: 1 | T36: =AVERAGE(O36:S36) -> 1 | AC36: =IF(J36="x",N36) -> 2.5 | AD36: =AC36*T36 -> 2.5
A37: 16 | B37: Las canecas están marcadas para diferenciar el tipo de desecho y están pintadas con color adecuado | J37: X | N37: 2.5 | O37: 1 | P37: 1 | Q37: 1 | R37: 1 | S37: 1 | T37: =AVERAGE(O37:S37) -> 1 | AC37: =IF(J37="x",N37) -> 2.5 | AD37: =AC37*T37 -> 2.5
A38: 17 | B38: Los desechos son evacuados máximo cada dos días por empresas publicas | J38: X | N38: 2.5 | O38: 1 | P38: 1 | Q38: 1 | R38: 1 | S38: 1 | T38: =AVERAGE(O38:S38) -> 1 | AC38: =IF(J38="x",N38) -> 2.5 | AD38: =AC38*T38 -> 2.5
A39: 18 | B39: Se usan canecas para escurrir los tarros de aceites y filtros | J39: X | N39: 2.5 | O39: 1 | P39: 1 | Q39: 1 | R39: 1 | S39: 1 | T39: =AVERAGE(O39:S39) -> 1 | AC39: =IF(J39="x",N39) -> 2.5 | AD39: =AC39*T39 -> 2.5
... A46: 25 | B46: Las unidades sanitarias se encuentran de acuerdo a lo especificado en los pliegos de condiciones y/o en la normativa vigente | J46: X | N46: 2.5 | O46: 1 | P46: 1 | Q46: 1 | R46: 1 | S46: 1 | T46: =AVERAGE(O46:S46) -> 1 | AC46: =IF(J46="x",N46) -> 2.5 | AD46: =AC46*T46 -> 2.5
A47: COMPONENTE C | U47: 20 | AC47: =IF(J47="x",N47) -> FALSE | AD47: =AC47*T47 -> 0
A48: 26 | B48: Las zonas verdes en el área de intervención de la obra se encuentran libres de materiales de construcción, a menos que se cuente con la autorización de la interventoría y/o la Autoridad Competente para uso temporal. Las zonas verdes usadas temporalmente deben quedan en condiciones iguales o mejores a las presentes antes de la afectación. | J48: X | N48: 4 | O48: 1 | P48: 1 | Q48: 1 | R48: 1 | S48: 1 | T48: =AVERAGE(O48:S48) -> 1 | U48: =IF(SUM(N48:N52)<>U47,"AJUSTAR PONDERACION",IF(SUM(AD48:AD52)=0,"",IF(SUM(AC48:AC52)=U47,IF(SUM(N48:N52)=U47,SUM(AD48:AD52),"Ajustar ponderacion"),"Ajustar ponderacion"))) -> 20 | AC48: =IF(J48="x",N48) -> 4 | AD48: =AC48*T48 -> 4
A49: 27 | B49: Sí existen individuos arbóreos en el área de influencia directa de la obra, éstos se encuentran debidamente protegidos según las especificaciones que al respecto se incluyen en el estipulado en el apéndice A&SST y sin afectación alguna por las actividades o acciones de obra. | J49: X | N49: 4 | O49: 1 | P49: 1 | Q49: 1 | R49: 1 | S49: 1 | T49: =AVERAGE(O49:S49) -> 1 | AC49: =IF(J49="x",N49) -> 4 | AD49: =AC49*T49 -> 4
A50: 28 | B50: Se realiza la ejecución de tratamientos silviculturales y el procedimiento de avifauna según lo estipulado por el Manual de Silvicultura Urbana del JBB y en cumplimiento de la Resolución de aprobación emitida por la AAC | J50: X | N50: 4 | O50: 1 | P50: 1 | Q50: 1 | R50: 1 | S50: 1 | T50: =AVERAGE(O50:S50) -> 1 | AC50: =IF(J50="x",N50) -> 4 | AD50: =AC50*T50 -> 4
A51: 29 | B51: Se realiza el seguimiento y mantenimiento periódico de los individuos vegetales del área de influencia del contrato. | J51: X | N51: 4 | O51: 1 | P51: 1 | Q51: 1 | R51: 1 | S51: 1 | T51: =AVERAGE(O51:S51) -> 1 | AC51: =IF(J51="x",N51) -> 4 | AD51: =AC51*T51 -> 4
A52: 27 | B52: Se cuenta con personal de medio ambiente encargado de realizar actividades en este tema | J52: X | N52: 4 | O52: 1 | P52: 1 | Q52: 1 | R52: 1 | S52: 1 | T52: =AVERAGE(O52:S52) -> 1 | AC52: =IF(J52="x",N52) -> 4 | AD52: =AC52*T52 -> 4
...

Sheet SEMANA 2
D1: LISTA DE CHEQUEO PARA PLAN DE MANEJO AMBIENTAL | K1: Código: GES-FO-082 Versión: 2 Fecha de Aprobación: 15-jun-2022 Clasificación: Público
B5: CONTRATO | C5: 703 del 2024 | E5: PROYECTO | F5: Parques y EP002 | H5: FASE O ETAPA | I5: 2 | K5: No. FASE / ETAPA: | L5: Obra
A8: PERIODO COMPRENDIDO ENTRE EL: | E8: 46035 | G8: Y EL | I8: 46039
A10: INFORME No. | D10: 7
A11: TIPO DE CONTRATO | D11: Obra
A12: OBJETO | D12: LA INTERVENTORÍA INTEGRAL (TÉCNICA, ADMINISTRATIVA, FINANCIERA, CONTABLE, LEGAL, AMBIENTAL Y DE SEGURIDAD Y SALUD EN EL TRABAJO) PARA REALIZAR LAS OBRAS DE CONSERVACIÓN Y CONSTRUCCIÓN DE: ESPACIO PUBLICO, PARQUES, PUENTES VEHICULARES Y/O PEATONALES SOBRE CUERPOS DE AGUA Y DE MALLA VIAL EN LA LOCALIDAD DE BOSA
A13: NOMBRE DEL PROYECTO | D13: Parques y EP002
A14: CONTRATISTA: | D14: CONSORCIO PARQUES Y EP002 | J14: CONTRATO No: | L14: 703 del 2024
A15: INTERVENTOR: | D15: CONSORCIO INFRAESTRUCTURA BOSA | J15: CONTRATO No: | L15: FDT-ATBOSA-I-028-2025
A16: SUPERVISOR: | D16: Dario Morales
A17: FECHA: | D17: 46053
N18: Porcentaje total de componentes 100% | O18: %Cump | P18: %Cumpli. | Q18: %Cumpli. | R18: %Cumpli. | S18: %Cumpli. | T18: %Cumpli.
A19: No. | B19: DESCRIPCIÓN | J19: SI | K19: NO | L19: N.A. | M19: RESUELTO | N19: PONDERACION | O19: 46035 | P19: 46036 | Q19: 46037 | R19: 46038 | S19: 46039 | T19: PROMEDIO | U19: Componente%
A20: COMPONENTE A | U20: 20 | AC20: Aplicabilidad | AD20: Ponderación
A21: 1 | B21: El contratista mantiene actualizado el contenido de las carpetas A&SST exigidas | J21: X | N21: 4 | O21: 0 | P21: 1 | Q21: 0 | R21: 1 | S21: 0 | T21: =AVERAGE(O21:S21) -> 0.4 | U21: =IF(SUM(N21:N25)<>U20,"Ajustar Ponderacion",IF(SUM(AD21:AD25)=0,"",IF(SUM(AC21:AC25)=U20,IF(SUM(N21:N25)=U20,SUM(AD21:AD25),"Ajustar ponderacion"),"Ajustar ponderacion"))) -> 17.6 | AC21: =IF(J21="x",N21) -> 4 | AD21: =AC21*T21 -> 1.6 | AF21: 0
A22: 2 | B22: Se cumple con el plan de acciones correctivas y/o preventivas a las observaciones en el ámbito A&SST hechas por la Interventoría en el desarrollo de las actividades del proyecto | J22: X | N22: 4 | O22: 1 | P22: 1 | Q22: 1 | R22: 1 | S22: 1 | T22: =AVERAGE(O22:S22) -> 1 | AC22: =IF(J22="x",N22) -> 4 | AD22: =AC22*T22 -> 4 | AF22: 100
A23: 3 | B23: La brigada de orden, aseo y limpieza – BOAL está conformada y dotada de acuerdo a lo especificado en el pliego de condiciones y cumple sus funciones. | J23: X | N23: 4 | O23: 1 | P23: 1 | Q23: 1 | R23: 1 | S23: 1 | T23: =AVERAGE(O23:S23) -> 1 | AC23: =IF(J23="x",N23) -> 4 | AD23: =AC23*T23 -> 4
A24: 4 | B24: Se entrega de manera oportuna de acuerdo a lo definido en los comités, todos los soportes de proveedores de materiales y sitio de disposición final de RCD producto de las actividades de obra. | J24: X | N24: 4 | O24: 1 | P24: 1 | Q24: 1 | R24: 1 | S24: 1 | T24: =AVERAGE(O24:S24) -> 1 | AC24: =IF(J24="x",N24) -> 4 | AD24: =AC24*T24 -> 4
A25: 5 | B25: Se cumple con todos los procedimientos ofertados en el MAO aprobado | J25: X | N25: 4 | O25: 1 | P25: 1 | Q25: 1 | R25: 1 | S25: 1 | T25: =AVERAGE(O25:S25) -> 1 | AC25: =IF(J25="x",N25) -> 4 | AD25: =AC25*T25 -> 4
A26: COMPONENTE B | U26: 50 | AC26: =IF(J26="x",N26) -> FALSE | AD26: =AC26*T26 -> 0
A27: 6 | B27: Hay escombros o materiales en espacio publico | J27: X | N27: 2.5 | O27: 1 | P27: 1 | Q27: 1 | R27: 1 | S27: 1 | T27: =AVERAGE(O27:S27) -> 1 | U27: =IF(SUM(N27:N46)<>U26,"Ajuste ponderacion",IF(SUM(AD27:AD46)=0,"",IF(SUM(AC27:AC46)=U26,IF(SUM(N27:N46)=U26,SUM(AD27:AD46),"ajustar ponderacion"),"ajustar ponderacion"))) -> 50 | AC27: =IF(J27="x",N27) -> 2.5 | AD27: =AC27*T27 -> 2.5
A28: 7 | B28: Los materiales de la obra están cubiertos con lonas, plásticos o geotextil y acordonados | J28: X | N28: 2.5 | O28: 1 | P28: 1 | Q28: 1 | R28: 1 | S28: 1 | T28: =AVERAGE(O28:S28) -> 1 | AC28: =IF(J28="x",N28) -> 2.5 | AD28: =AC28*T28 -> 2.5
A29: 8 | B29: Se implementan las medidas de manejo necesarias para impedir el aporte de sólidos o sustancias contaminantes al sistema de alcantarillado o cuerpos de agua. | J29: X | N29: 2.5 | O29: 1 | P29: 1 | Q29: 1 | R29: 1 | S29: 1 | T29: =AVERAGE(O29:S29) -> 1 | AC29: =IF(J29="x",N29) -> 2.5 | AD29: =AC29*T29 -> 2.5
A30: 9 | B30: El campamento de obra se encuentra debidamente demarcado, señalizado, ordenado y aseado de acuerdo a lo ofertado en el MAO. | J30: X | N30: 2.5 | O30: 1 | P30: 1 | Q30: 1 | R30: 1 | S30: 1 | T30: =AVERAGE(O30:S30) -> 1 | AC30: =IF(J30="x",N30) -> 2.5 | AD30: =AC30*T30 -> 2.5
A31: 10 | B31: Existe aislamiento del equipo y operario en uso de cortadora, para mitigar el material particulado | J31: X | N31: 2.5 | O31: 1 | P31: 1 | Q31: 1 | R31: 1 | S31: 1 | T31: =AVERAGE(O31:S31) -> 1 | AC31: =IF(J31="x",N31) -> 2.5 | AD31: =AC31*T31 -> 2.5
A32: 11 | B32: Los materiales almacenados interfieren el trafico peatonal, vehicular y espacio publico | J32: X | N32: 2.5 | O32: 1 | P32: 1 | Q32: 1 | R32: 1 | S32: 1 | T32: =AVERAGE(O32:S32) -> 1 | AC32: =IF(J32="x",N32) -> 2.5 | AD32: =AC32*T32 -> 2.5
A33: 12 | B33: Los vehículos para transporte de material no exceden su capacidad, están cubiertos los escombros | J33: X | N33: 2.5 | O33: 1 | P33: 1 | Q33: 1 | R33: 1 | S33: 1 | T33: =AVERAGE(O33:S33) -> 1 | AC33: =IF(J33="x",N33) -> 2.5 | AD33: =AC33*T33 -> 2.5
A34: 13 | B34: Se garantiza la limpieza de las llantas de todos los vehículos que salen de la obra | J34: X | N34: 2.5 | O34: 1 | P34: 1 | Q34: 1 | R34: 1 | S34: 1 | T34: =AVERAGE(O34:S34) -> 1 | AC34: =IF(J34="x",N34) -> 2.5 | AD34: =AC34*T34 -> 2.5
A35: 14 | B35: Se limpia el lugar donde se cargan las volquetas | J35: X | N35: 2.5 | O35: 1 | P35: 1 | Q35: 1 | R35: 1 | S35: 1 | T35: =AVERAGE(O35:S35) -> 1 | AC35: =IF(J35="x",N35) -> 2.5 | AD35: =AC35*T35 -> 2.5
A36: 15 | B36: Se realiza la disposición final de los escombros en lugar autorizado | J36: X | N36: 2.5 | O36: 1 | P36: 1 | Q36: 1 | R36: 1 | S36: 1 | T36: =AVERAGE(O36:S36) -> 1 | AC36: =IF(J36="x",N36) -> 2.5 | AD36: =AC36*T36 -> 2.5
A37: 16 | B37: Las canecas están marcadas para diferenciar el tipo de desecho y están pintadas con color adecuado | J37: X | N37: 2.5 | O37: 1 | P37: 1 | Q37: 1 | R37: 1 | S37: 1 | T37: =AVERAGE(O37:S37) -> 1 | AC37: =IF(J37="x",N37) -> 2.5 | AD37: =AC37*T37 -> 2.5
A38: 17 | B38: Los desechos son evacuados máximo cada dos días por empresas publicas | J38: X | N38: 2.5 | O38: 1 | P38: 1 | Q38: 1 | R38: 1 | S38: 1 | T38: =AVERAGE(O38:S38) -> 1 | AC38: =IF(J38="x",N38) -> 2.5 | AD38: =AC38*T38 -> 2.5
A39: 18 | B39: Se usan canecas para escurrir los tarros de aceites y filtros | J39: X | N39: 2.5 | O39: 1 | P39: 1 | Q39: 1 | R39: 1 | S39: 1 | T39: =AVERAGE(O39:S39) -> 1 | AC39: =IF(J39="x",N39) -> 2.5 | AD39: =AC39*T39 -> 2.5
... A46: 25 | B46: Las unidades sanitarias se encuentran de acuerdo a lo especificado en los pliegos de condiciones y/o en la normativa vigente | J46: X | N46: 2.5 | O46: 1 | P46: 1 | Q46: 1 | R46: 1 | S46: 1 | T46: =AVERAGE(O46:S46) -> 1 | AC46: =IF(J46="x",N46) -> 2.5 | AD46: =AC46*T46 -> 2.5
A47: COMPONENTE C | U47: 20 | AC47: =IF(J47="x",N47) -> FALSE | AD47: =AC47*T47 -> 0
A48: 26 | B48: Las zonas verdes en el área de intervención de la obra se encuentran libres de materiales de construcción, a menos que se cuente con la autorización de la interventoría y/o la Autoridad Competente para uso temporal. Las zonas verdes usadas temporalmente deben quedan en condiciones iguales o mejores a las presentes antes de la afectación. | J48: X | N48: 4 | O48: 1 | P48: 1 | Q48: 1 | R48: 1 | S48: 1 | T48: =AVERAGE(O48:S48) -> 1 | U48: =IF(SUM(N48:N52)<>U47,"AJUSTAR PONDERACION",IF(SUM(AD48:AD52)=0,"",IF(SUM(AC48:AC52)=U47,IF(SUM(N48:N52)=U47,SUM(AD48:AD52),"Ajustar ponderacion"),"Ajustar ponderacion"))) -> 20 | AC48: =IF(J48="x",N48) -> 4 | AD48: =AC48*T48 -> 4
A49: 27 | B49: Sí existen individuos arbóreos en el área de influencia directa de la obra, éstos se encuentran debidamente protegidos según las especificaciones que al respecto se incluyen en el estipulado en el apéndice A&SST y sin afectación alguna por las actividades o acciones de obra. | J49: X | N49: 4 | O49: 1 | P49: 1 | Q49: 1 | R49: 1 | S49: 1 | T49: =AVERAGE(O49:S49) -> 1 | AC49: =IF(J49="x",N49) -> 4 | AD49: =AC49*T49 -> 4
A50: 28 | B50: Se realiza la ejecución de tratamientos silviculturales y el procedimiento de avifauna según lo estipulado por el Manual de Silvicultura Urbana del JBB y en cumplimiento de la Resolución de aprobación emitida por la AAC | J50: X | N50: 4 | O50: 1 | P50: 1 | Q50: 1 | R50: 1 | S50: 1 | T50: =AVERAGE(O50:S50) -> 1 | AC50: =IF(J50="x",N50) -> 4 | AD50: =AC50*T50 -> 4
A51: 29 | B51: Se realiza el seguimiento y mantenimiento periódico de los individuos vegetales del área de influencia del contrato. | J51: X | N51: 4 | O51: 1 | P51: 1 | Q51: 1 | R51: 1 | S51: 1 | T51: =AVERAGE(O51:S51) -> 1 | AC51: =IF(J51="x",N51) -> 4 | AD51: =AC51*T51 -> 4
A52: 27 | B52: Se cuenta con personal de medio ambiente encargado de realizar actividades en este tema | J52: X | N52: 4 | O52: 1 | P52: 1 | Q52: 1 | R52: 1 | S52: 1 | T52: =AVERAGE(O52:S52) -> 1 | AC52: =IF(J52="x",N52) -> 4 | AD52: =AC52*T52 -> 4
...

Sheet SEMANA 3
D1: LISTA DE CHEQUEO PARA PLAN DE MANEJO AMBIENTAL | K1: Código: GES-FO-082 Versión: 2 Fecha de Aprobación: 15-jun-2022 Clasificación: Público
B5: CONTRATO | C5: 703 del 2024 | E5: PROYECTO | F5: Parques y EP002 | H5: FASE O ETAPA | I5: 2 | K5: No. FASE / ETAPA: | L5: Obra
A8: PERIODO COMPRENDIDO ENTRE EL: | E8: 46041 | G8: Y EL | I8: 46045
A10: INFORME No. | D10: 7
A11: TIPO DE CONTRATO | D11: Obra
A12: OBJETO | D12: LA INTERVENTORÍA INTEGRAL (TÉCNICA, ADMINISTRATIVA, FINANCIERA, CONTABLE, LEGAL, AMBIENTAL Y DE SEGURIDAD Y SALUD EN EL TRABAJO) PARA REALIZAR LAS OBRAS DE CONSERVACIÓN Y CONSTRUCCIÓN DE: ESPACIO PUBLICO, PARQUES, PUENTES VEHICULARES Y/O PEATONALES SOBRE CUERPOS DE AGUA Y DE MALLA VIAL EN LA LOCALIDAD DE BOSA
A13: NOMBRE DEL PROYECTO | D13: Parques y EP002
A14: CONTRATISTA: | D14: CONSORCIO PARQUES Y EP002 | J14: CONTRATO No: | L14: 703 del 2024
A15: INTERVENTOR: | D15: CONSORCIO INFRAESTRUCTURA BOSA | J15: CONTRATO No: | L15: FDT-ATBOSA-I-028-2025
A16: SUPERVISOR: | D16: Dario Morales
A17: FECHA: | D17: 46053
N18: Porcentaje total de componentes 100% | O18: %Cump | P18: %Cumpli. | Q18: %Cumpli. | R18: %Cumpli. | S18: %Cumpli. | T18: %Cumpli.
A19: No. | B19: DESCRIPCIÓN | J19: SI | K19: NO | L19: N.A. | M19: RESUELTO | N19: PONDERACION | O19: 46041 | P19: 46042 | Q19: 46043 | R19: 46044 | S19: 46045 | T19: PROMEDIO | U19: Componente%
A20: COMPONENTE A | U20: 20 | AC20: Aplicabilidad | AD20: Ponderación
A21: 1 | B21: El contratista mantiene actualizado el contenido de las carpetas A&SST exigidas | J21: X | N21: 4 | O21: 0 | P21: 0 | Q21: 0 | R21: 0 | S21: 1 | T21: =AVERAGE(O21:S21) -> 0.2 | U21: =IF(SUM(N21:N25)<>U20,"Ajustar Ponderacion",IF(SUM(AD21:AD25)=0,"",IF(SUM(AC21:AC25)=U20,IF(SUM(N21:N25)=U20,SUM(AD21:AD25),"Ajustar ponderacion"),"Ajustar ponderacion"))) -> 16.8 | AC21: =IF(J21="x",N21) -> 4 | AD21: =AC21*T21 -> 0.8 | AF21: 0
A22: 2 | B22: Se cumple con el plan de acciones correctivas y/o preventivas a las observaciones en el ámbito A&SST hechas por la Interventoría en el desarrollo de las actividades del proyecto | J22: X | N22: 4 | O22: 1 | P22: 1 | Q22: 1 | R22: 1 | S22: 1 | T22: =AVERAGE(O22:S22) -> 1 | AC22: =IF(J22="x",N22) -> 4 | AD22: =AC22*T22 -> 4 | AF22: 100
A23: 3 | B23: La brigada de orden, aseo y limpieza – BOAL está conformada y dotada de acuerdo a lo especificado en el pliego de condiciones y cumple sus funciones. | J23: X | N23: 4 | O23: 1 | P23: 1 | Q23: 1 | R23: 1 | S23: 1 | T23: =AVERAGE(O23:S23) -> 1 | AC23: =IF(J23="x",N23) -> 4 | AD23: =AC23*T23 -> 4
A24: 4 | B24: Se entrega de manera oportuna de acuerdo a lo definido en los comités, todos los soportes de proveedores de materiales y sitio de disposición final de RCD producto de las actividades de obra. | J24: X | N24: 4 | O24: 1 | P24: 1 | Q24: 1 | R24: 1 | S24: 1 | T24: =AVERAGE(O24:S24) -> 1 | AC24: =IF(J24="x",N24) -> 4 | AD24: =AC24*T24 -> 4
A25: 5 | B25: Se cumple con todos los procedimientos ofertados en el MAO aprobado | J25: X | N25: 4 | O25: 1 | P25: 1 | Q25: 1 | R25: 1 | S25: 1 | T25: =AVERAGE(O25:S25) -> 1 | AC25: =IF(J25="x",N25) -> 4 | AD25: =AC25*T25 -> 4
A26: COMPONENTE B | U26: 50 | AC26: =IF(J26="x",N26) -> FALSE | AD26: =AC26*T26 -> 0
A27: 6 | B27: Hay escombros o materiales en espacio publico | J27: X | N27: 2.5 | O27: 1 | P27: 1 | Q27: 1 | R27: 1 | S27: 1 | T27: =AVERAGE(O27:S27) -> 1 | U27: =IF(SUM(N27:N46)<>U26,"Ajuste ponderacion",IF(SUM(AD27:AD46)=0,"",IF(SUM(AC27:AC46)=U26,IF(SUM(N27:N46)=U26,SUM(AD27:AD46),"ajustar ponderacion"),"ajustar ponderacion"))) -> 50 | AC27: =IF(J27="x",N27) -> 2.5 | AD27: =AC27*T27 -> 2.5
A28: 7 | B28: Los materiales de la obra están cubiertos con lonas, plásticos o geotextil y acordonados | J28: X | N28: 2.5 | O28: 1 | P28: 1 | Q28: 1 | R28: 1 | S28: 1 | T28: =AVERAGE(O28:S28) -> 1 | AC28: =IF(J28="x",N28) -> 2.5 | AD28: =AC28*T28 -> 2.5
A29: 8 | B29: Se implementan las medidas de manejo necesarias para impedir el aporte de sólidos o sustancias contaminantes al sistema de alcantarillado o cuerpos de agua. | J29: X | N29: 2.5 | O29: 1 | P29: 1 | Q29: 1 | R29: 1 | S29: 1 | T29: =AVERAGE(O29:S29) -> 1 | AC29: =IF(J29="x",N29) -> 2.5 | AD29: =AC29*T29 -> 2.5
A30: 9 | B30: El campamento de obra se encuentra debidamente demarcado, señalizado, ordenado y aseado de acuerdo a lo ofertado en el MAO. | J30: X | N30: 2.5 | O30: 1 | P30: 1 | Q30: 1 | R30: 1 | S30: 1 | T30: =AVERAGE(O30:S30) -> 1 | AC30: =IF(J30="x",N30) -> 2.5 | AD30: =AC30*T30 -> 2.5
A31: 10 | B31: Existe aislamiento del equipo y operario en uso de cortadora, para mitigar el material particulado | J31: X | N31: 2.5 | O31: 1 | P31: 1 | Q31: 1 | R31: 1 | S31: 1 | T31: =AVERAGE(O31:S31) -> 1 | AC31: =IF(J31="x",N31) -> 2.5 | AD31: =AC31*T31 -> 2.5
A32: 11 | B32: Los materiales almacenados interfieren el trafico peatonal, vehicular y espacio publico | J32: X | N32: 2.5 | O32: 1 | P32: 1 | Q32: 1 | R32: 1 | S32: 1 | T32: =AVERAGE(O32:S32) -> 1 | AC32: =IF(J32="x",N32) -> 2.5 | AD32: =AC32*T32 -> 2.5
A33: 12 | B33: Los vehículos para transporte de material no exceden su capacidad, están cubiertos los escombros | J33: X | N33: 2.5 | O33: 1 | P33: 1 | Q33: 1 | R33: 1 | S33: 1 | T33: =AVERAGE(O33:S33) -> 1 | AC33: =IF(J33="x",N33) -> 2.5 | AD33: =AC33*T33 -> 2.5
A34: 13 | B34: Se garantiza la limpieza de las llantas de todos los vehículos que salen de la obra | J34: X | N34: 2.5 | O34: 1 | P34: 1 | Q34: 1 | R34: 1 | S34: 1 | T34: =AVERAGE(O34:S34) -> 1 | AC34: =IF(J34="x",N34) -> 2.5 | AD34: =AC34*T34 -> 2.5
A35: 14 | B35: Se limpia el lugar donde se cargan las volquetas | J35: X | N35: 2.5 | O35: 1 | P35: 1 | Q35: 1 | R35: 1 | S35: 1 | T35: =AVERAGE(O35:S35) -> 1 | AC35: =IF(J35="x",N35) -> 2.5 | AD35: =AC35*T35 -> 2.5
A36: 15 | B36: Se realiza la disposición final de los escombros en lugar autorizado | J36: X | N36: 2.5 | O36: 1 | P36: 1 | Q36: 1 | R36: 1 | S36: 1 | T36: =AVERAGE(O36:S36) -> 1 | AC36: =IF(J36="x",N36) -> 2.5 | AD36: =AC36*T36 -> 2.5
A37: 16 | B37: Las canecas están marcadas para diferenciar el tipo de desecho y están pintadas con color adecuado | J37: X | N37: 2.5 | O37: 1 | P37: 1 | Q37: 1 | R37: 1 | S37: 1 | T37: =AVERAGE(O37:S37) -> 1 | AC37: =IF(J37="x",N37) -> 2.5 | AD37: =AC37*T37 -> 2.5
A38: 17 | B38: Los desechos son evacuados máximo cada dos días por empresas publicas | J38: X | N38: 2.5 | O38: 1 | P38: 1 | Q38: 1 | R38: 1 | S38: 1 | T38: =AVERAGE(O38:S38) -> 1 | AC38: =IF(J38="x",N38) -> 2.5 | AD38: =AC38*T38 -> 2.5
A39: 18 | B39: Se usan canecas para escurrir los tarros de aceites y filtros | J39: X | N39: 2.5 | O39: 1 | P39: 1 | Q39: 1 | R39: 1 | S39: 1 | T39: =AVERAGE(O39:S39) -> 1 | AC39: =IF(J39="x",N39) -> 2.5 | AD39: =AC39*T39 -> 2.5
... A46: 25 | B46: Las unidades sanitarias se encuentran de acuerdo a lo especificado en los pliegos de condiciones y/o en la normativa vigente | J46: X | N46: 2.5 | O46: 1 | P46: 1 | Q46: 1 | R46: 1 | S46: 1 | T46: =AVERAGE(O46:S46) -> 1 | AC46: =IF(J46="x",N46) -> 2.5 | AD46: =AC46*T46 -> 2.5
A47: COMPONENTE C | U47: 20 | AC47: =IF(J47="x",N47) -> FALSE | AD47: =AC47*T47 -> 0
A48: 26 | B48: Las zonas verdes en el área de intervención de la obra se encuentran libres de materiales de construcción, a menos que se cuente con la autorización de la interventoría y/o la Autoridad Competente para uso temporal. Las zonas verdes usadas temporalmente deben quedan en condiciones iguales o mejores a las presentes antes de la afectación. | J48: X | N48: 4 | O48: 1 | P48: 1 | Q48: 1 | R48: 1 | S48: 1 | T48: =AVERAGE(O48:S48) -> 1 | U48: =IF(SUM(N48:N52)<>U47,"AJUSTAR PONDERACION",IF(SUM(AD48:AD52)=0,"",IF(SUM(AC48:AC52)=U47,IF(SUM(N48:N52)=U47,SUM(AD48:AD52),"Ajustar ponderacion"),"Ajustar ponderacion"))) -> 20 | AC48: =IF(J48="x",N48) -> 4 | AD48: =AC48*T48 -> 4
A49: 27 | B49: Sí existen individuos arbóreos en el área de influencia directa de la obra, éstos se encuentran debidamente protegidos según las especificaciones que al respecto se incluyen en el estipulado en el apéndice A&SST y sin afectación alguna por las actividades o acciones de obra. | J49: X | N49: 4 | O49: 1 | P49: 1 | Q49: 1 | R49: 1 | S49: 1 | T49: =AVERAGE(O49:S49) -> 1 | AC49: =IF(J49="x",N49) -> 4 | AD49: =AC49*T49 -> 4
A50: 28 | B50: Se realiza la ejecución de tratamientos silviculturales y el procedimiento de avifauna según lo estipulado por el Manual de Silvicultura Urbana del JBB y en cumplimiento de la Resolución de aprobación emitida por la AAC | J50: X | N50: 4 | O50: 1 | P50: 1 | Q50: 1 | R50: 1 | S50: 1 | T50: =AVERAGE(O50:S50) -> 1 | AC50: =IF(J50="x",N50) -> 4 | AD50: =AC50*T50 -> 4
A51: 29 | B51: Se realiza el seguimiento y mantenimiento periódico de los individuos vegetales del área de influencia del contrato. | J51: X | N51: 4 | O51: 1 | P51: 1 | Q51: 1 | R51: 1 | S51: 1 | T51: =AVERAGE(O51:S51) -> 1 | AC51: =IF(J51="x",N51) -> 4 | AD51: =AC51*T51 -> 4
A52: 27 | B52: Se cuenta con personal de medio ambiente encargado de realizar actividades en este tema | J52: X | N52: 4 | O52: 1 | P52: 1 | Q52: 1 | R52: 1 | S52: 1 | T52: =AVERAGE(O52:S52) -> 1 | AC52: =IF(J52="x",N52) -> 4 | AD52: =AC52*T52 -> 4
...

Sheet SEMANA 4
D1: LISTA DE CHEQUEO PARA PLAN DE MANEJO AMBIENTAL | K1: Código: GES-FO-082 Versión: 2 Fecha de Aprobación: 15-jun-2022 Clasificación: Público
B5: CONTRATO | C5: 703 del 2024 | E5: PROYECTO | F5: Parques y EP002 | H5: FASE O ETAPA | I5: 2 | K5: No. FASE / ETAPA: | L5: Obra
A8: PERIODO COMPRENDIDO ENTRE EL: | E8: 46048 | G8: Y EL | I8: 46053
A10: INFORME No. | D10: 7
A11: TIPO DE CONTRATO | D11: Obra
A12: OBJETO | D12: LA INTERVENTORÍA INTEGRAL (TÉCNICA, ADMINISTRATIVA, FINANCIERA, CONTABLE, LEGAL, AMBIENTAL Y DE SEGURIDAD Y SALUD EN EL TRABAJO) PARA REALIZAR LAS OBRAS DE CONSERVACIÓN Y CONSTRUCCIÓN DE: ESPACIO PUBLICO, PARQUES, PUENTES VEHICULARES Y/O PEATONALES SOBRE CUERPOS DE AGUA Y DE MALLA VIAL EN LA LOCALIDAD DE BOSA
A13: NOMBRE DEL PROYECTO | D13: Parques y EP002
A14: CONTRATISTA: | D14: CONSORCIO PARQUES Y EP002 | J14: CONTRATO No: | L14: 703 del 2024
A15: INTERVENTOR: | D15: CONSORCIO INFRAESTRUCTURA BOSA | J15: CONTRATO No: | L15: FDT-ATBOSA-I-028-2025
A16: SUPERVISOR: | D16: Dario Morales
A17: FECHA: | D17: 46053
N18: Porcentaje total de componentes 100% | O18: %Cump | P18: %Cumpli. | Q18: %Cumpli. | R18: %Cumpli. | S18: %Cumpli. | T18: %Cumpli.
A19: No. | B19: DESCRIPCIÓN | J19: SI | K19: NO | L19: N.A. | M19: RESUELTO | N19: PONDERACION | O19: 46048 | P19: 46049 | Q19: 46050 | R19: 46051 | S19: 46052 | T19: PROMEDIO | U19: Componente%
A20: COMPONENTE A | U20: 20 | AC20: Aplicabilidad | AD20: Ponderación
A21: 1 | B21: El contratista mantiene actualizado el contenido de las carpetas A&SST exigidas | J21: X | N21: 4 | O21: 1 | P21: 1 | Q21: 1 | R21: 1 | S21: 1 | T21: =AVERAGE(O21:S21) -> 1 | U21: =IF(SUM(N21:N25)<>U20,"Ajustar Ponderacion",IF(SUM(AD21:AD25)=0,"",IF(SUM(AC21:AC25)=U20,IF(SUM(N21:N25)=U20,SUM(AD21:AD25),"Ajustar ponderacion"),"Ajustar ponderacion"))) -> 20 | AC21: =IF(J21="x",N21) -> 4 | AD21: =AC21*T21 -> 4 | AF21: 0
A22: 2 | B22: Se cumple con el plan de acciones correctivas y/o preventivas a las observaciones en el ámbito A&SST hechas por la Interventoría en el desarrollo de las actividades del proyecto | J22: X | N22: 4 | O22: 1 | P22: 1 | Q22: 1 | R22: 1 | S22: 1 | T22: =AVERAGE(O22:S22) -> 1 | AC22: =IF(J22="x",N22) -> 4 | AD22: =AC22*T22 -> 4 | AF22: 100
A23: 3 | B23: La brigada de orden, aseo y limpieza – BOAL está conformada y dotada de acuerdo a lo especificado en el pliego de condiciones y cumple sus funciones. | J23: X | N23: 4 | O23: 1 | P23: 1 | Q23: 1 | R23: 1 | S23: 1 | T23: =AVERAGE(O23:S23) -> 1 | AC23: =IF(J23="x",N23) -> 4 | AD23: =AC23*T23 -> 4
A24: 4 | B24: Se entrega de manera oportuna de acuerdo a lo definido en los comités, todos los soportes de proveedores de materiales y sitio de disposición final de RCD producto de las actividades de obra. | J24: X | N24: 4 | O24: 1 | P24: 1 | Q24: 1 | R24: 1 | S24: 1 | T24: =AVERAGE(O24:S24) -> 1 | AC24: =IF(J24="x",N24) -> 4 | AD24: =AC24*T24 -> 4
A25: 5 | B25: Se cumple con todos los procedimientos ofertados en el MAO aprobado | J25: X | N25: 4 | O25: 1 | P25: 1 | Q25: 1 | R25: 1 | S25: 1 | T25: =AVERAGE(O25:S25) -> 1 | AC25: =IF(J25="x",N25) -> 4 | AD25: =AC25*T25 -> 4
A26: COMPONENTE B | U26: 50 | AC26: =IF(J26="x",N26) -> FALSE | AD26: =AC26*T26 -> 0
A27: 6 | B27: Hay escombros o materiales en espacio publico | J27: X | N27: 2.5 | O27: 1 | P27: 1 | Q27: 1 | R27: 0 | S27: 0 | T27: =AVERAGE(O27:S27) -> 0.6 | U27: =IF(SUM(N27:N46)<>U26,"Ajuste ponderacion",IF(SUM(AD27:AD46)=0,"",IF(SUM(AC27:AC46)=U26,IF(SUM(N27:N46)=U26,SUM(AD27:AD46),"ajustar ponderacion"),"ajustar ponderacion"))) -> 47.5 | AC27: =IF(J27="x",N27) -> 2.5 | AD27: =AC27*T27 -> 1.5
A28: 7 | B28: Los materiales de la obra están cubiertos con lonas, plásticos o geotextil y acordonados | J28: X | N28: 2.5 | O28: 1 | P28: 0 | Q28: 0 | R28: 0 | S28: 1 | T28: =AVERAGE(O28:S28) -> 0.4 | AC28: =IF(J28="x",N28) -> 2.5 | AD28: =AC28*T28 -> 1
A29: 8 | B29: Se implementan las medidas de manejo necesarias para impedir el aporte de sólidos o sustancias contaminantes al sistema de alcantarillado o cuerpos de agua. | J29: X | N29: 2.5 | O29: 1 | P29: 1 | Q29: 1 | R29: 1 | S29: 1 | T29: =AVERAGE(O29:S29) -> 1 | AC29: =IF(J29="x",N29) -> 2.5 | AD29: =AC29*T29 -> 2.5
A30: 9 | B30: El campamento de obra se encuentra debidamente demarcado, señalizado, ordenado y aseado de acuerdo a lo ofertado en el MAO. | J30: X | N30: 2.5 | O30: 1 | P30: 1 | Q30: 1 | R30: 1 | S30: 1 | T30: =AVERAGE(O30:S30) -> 1 | AC30: =IF(J30="x",N30) -> 2.5 | AD30: =AC30*T30 -> 2.5
A31: 10 | B31: Existe aislamiento del equipo y operario en uso de cortadora, para mitigar el material particulado | J31: X | N31: 2.5 | O31: 1 | P31: 1 | Q31: 1 | R31: 1 | S31: 1 | T31: =AVERAGE(O31:S31) -> 1 | AC31: =IF(J31="x",N31) -> 2.5 | AD31: =AC31*T31 -> 2.5
A32: 11 | B32: Los materiales almacenados interfieren el trafico peatonal, vehicular y espacio publico | J32: X | N32: 2.5 | O32: 1 | P32: 1 | Q32: 1 | R32: 1 | S32: 1 | T32: =AVERAGE(O32:S32) -> 1 | AC32: =IF(J32="x",N32) -> 2.5 | AD32: =AC32*T32 -> 2.5
A33: 12 | B33: Los vehículos para transporte de material no exceden su capacidad, están cubiertos los escombros | J33: X | N33: 2.5 | O33: 1 | P33: 1 | Q33: 1 | R33: 1 | S33: 1 | T33: =AVERAGE(O33:S33) -> 1 | AC33: =IF(J33="x",N33) -> 2.5 | AD33: =AC33*T33 -> 2.5
A34: 13 | B34: Se garantiza la limpieza de las llantas de todos los vehículos que salen de la obra | J34: X | N34: 2.5 | O34: 1 | P34: 1 | Q34: 1 | R34: 1 | S34: 1 | T34: =AVERAGE(O34:S34) -> 1 | AC34: =IF(J34="x",N34) -> 2.5 | AD34: =AC34*T34 -> 2.5
A35: 14 | B35: Se limpia el lugar donde se cargan las volquetas | J35: X | N35: 2.5 | O35: 1 | P35: 1 | Q35: 1 | R35: 1 | S35: 1 | T35: =AVERAGE(O35:S35) -> 1 | AC35: =IF(J35="x",N35) -> 2.5 | AD35: =AC35*T35 -> 2.5
A36: 15 | B36: Se realiza la disposición final de los escombros en lugar autorizado | J36: X | N36: 2.5 | O36: 1 | P36: 1 | Q36: 1 | R36: 1 | S36: 1 | T36: =AVERAGE(O36:S36) -> 1 | AC36: =IF(J36="x",N36) -> 2.5 | AD36: =AC36*T36 -> 2.5
A37: 16 | B37: Las canecas están marcadas para diferenciar el tipo de desecho y están pintadas con color adecuado | J37: X | N37: 2.5 | O37: 1 | P37: 1 | Q37: 1 | R37: 1 | S37: 1 | T37: =AVERAGE(O37:S37) -> 1 | AC37: =IF(J37="x",N37) -> 2.5 | AD37: =AC37*T37 -> 2.5
A38: 17 | B38: Los desechos son evacuados máximo cada dos días por empresas publicas | J38: X | N38: 2.5 | O38: 1 | P38: 1 | Q38: 1 | R38: 1 | S38: 1 | T38: =AVERAGE(O38:S38) -> 1 | AC38: =IF(J38="x",N38) -> 2.5 | AD38: =AC38*T38 -> 2.5
A39: 18 | B39: Se usan canecas para escurrir los tarros de aceites y filtros | J39: X | N39: 2.5 | O39: 1 | P39: 1 | Q39: 1 | R39: 1 | S39: 1 | T39: =AVERAGE(O39:S39) -> 1 | AC39: =IF(J39="x",N39) -> 2.5 | AD39: =AC39*T39 -> 2.5
... A46: 25 | B46: Las unidades sanitarias se encuentran de acuerdo a lo especificado en los pliegos de condiciones y/o en la normativa vigente | J46: X | N46: 2.5 | O46: 1 | P46: 1 | Q46: 1 | R46: 1 | S46: 1 | T46: =AVERAGE(O46:S46) -> 1 | AC46: =IF(J46="x",N46) -> 2.5 | AD46: =AC46*T46 -> 2.5
A47: COMPONENTE C | U47: 20 | AC47: =IF(J47="x",N47) -> FALSE | AD47: =AC47*T47 -> 0
A48: 26 | B48: Las zonas verdes en el área de intervención de la obra se encuentran libres de materiales de construcción, a menos que se cuente con la autorización de la interventoría y/o la Autoridad Competente para uso temporal. Las zonas verdes usadas temporalmente deben quedan en condiciones iguales o mejores a las presentes antes de la afectación. | J48: X | N48: 4 | O48: 1 | P48: 1 | Q48: 1 | R48: 1 | S48: 1 | T48: =AVERAGE(O48:S48) -> 1 | U48: =IF(SUM(N48:N52)<>U47,"AJUSTAR PONDERACION",IF(SUM(AD48:AD52)=0,"",IF(SUM(AC48:AC52)=U47,IF(SUM(N48:N52)=U47,SUM(AD48:AD52),"Ajustar ponderacion"),"Ajustar ponderacion"))) -> 20 | AC48: =IF(J48="x",N48) -> 4 | AD48: =AC48*T48 -> 4
A49: 27 | B49: Sí existen individuos arbóreos en el área de influencia directa de la obra, éstos se encuentran debidamente protegidos según las especificaciones que al respecto se incluyen en el estipulado en el apéndice A&SST y sin afectación alguna por las actividades o acciones de obra. | J49: X | N49: 4 | O49: 1 | P49: 1 | Q49: 1 | R49: 1 | S49: 1 | T49: =AVERAGE(O49:S49) -> 1 | AC49: =IF(J49="x",N49) -> 4 | AD49: =AC49*T49 -> 4
A50: 28 | B50: Se realiza la ejecución de tratamientos silviculturales y el procedimiento de avifauna según lo estipulado por el Manual de Silvicultura Urbana del JBB y en cumplimiento de la Resolución de aprobación emitida por la AAC | J50: X | N50: 4 | O50: 1 | P50: 1 | Q50: 1 | R50: 1 | S50: 1 | T50: =AVERAGE(O50:S50) -> 1 | AC50: =IF(J50="x",N50) -> 4 | AD50: =AC50*T50 -> 4
A51: 29 | B51: Se realiza el seguimiento y mantenimiento periódico de los individuos vegetales del área de influencia del contrato. | J51: X | N51: 4 | O51: 1 | P51: 1 | Q51: 1 | R51: 1 | S51: 1 | T51: =AVERAGE(O51:S51) -> 1 | AC51: =IF(J51="x",N51) -> 4 | AD51: =AC51*T51 -> 4
A52: 27 | B52: Se cuenta con personal de medio ambiente encargado de realizar actividades en este tema | J52: X | N52: 4 | O52: 1 | P52: 1 | Q52: 1 | R52: 1 | S52: 1 | T52: =AVERAGE(O52:S52) -> 1 | AC52: =IF(J52="x",N52) -> 4 | AD52: =AC52*T52 -> 4
...

Sheet CONSOLIDADO MES
D1: LISTA DE CHEQUEO PARA PLAN DE MANEJO AMBIENTAL | K1: Código: GES-FO-082 Versión: 2 Fecha de Aprobación: 15-jun-2022 Clasificación: Público
B5: CONTRATO | C5: 703 del 2024 | E5: PROYECTO | F5: Parques y EP002 | H5: FASE O ETAPA | I5: 2 | K5: No. FASE / ETAPA: | L5: Obra
A8: PERIODO COMPRENDIDO ENTRE EL: | E8: 46023 | G8: Y EL | I8: 46053
A10: INFORME No. | D10: 7
A11: TIPO DE CONTRATO | D11: Obra
A12: OBJETO | D12: LA INTERVENTORÍA INTEGRAL (TÉCNICA, ADMINISTRATIVA, FINANCIERA, CONTABLE, LEGAL, AMBIENTAL Y DE SEGURIDAD Y SALUD EN EL TRABAJO) PARA REALIZAR LAS OBRAS DE CONSERVACIÓN Y CONSTRUCCIÓN DE: ESPACIO PUBLICO, PARQUES, PUENTES VEHICULARES Y/O PEATONALES SOBRE CUERPOS DE AGUA Y DE MALLA VIAL EN LA LOCALIDAD DE BOSA
A13: NOMBRE DEL PROYECTO | D13: Parques y EP002
A14: CONTRATISTA: | D14: CONSORCIO PARQUES Y EP002 | J14: CONTRATO No: | L14: 703 del 2024
A15: INTERVENTOR: | D15: CONSORCIO INFRAESTRUCTURA BOSA | J15: CONTRATO No: | L15: FDT-ATBOSA-I-028-2025
A16: SUPERVISOR: | D16: Dario Morales
A17: FECHA: | D17: 46053
N18: Porcentaje total de componentes 100% | O18: %Cump | P18: %Cump | Q18: %Cumpli. | R18: %Cumpli. | S18: %Cumpli. | T18: Observaciones
A19: No. | B19: DESCRIPCIÓN | J19: SI | K19: NO | L19: N.A. | M19: RESUELTO | N19: PONDERACION | O19: SEMANA 1 | P19: SEMANA 2 | Q19: SEMANA 3 | R19: SEMANA 4 | S19: PROMEDIO | U19: Componente%
A20: COMPONENTE A | U20: 20 | AC20: Aplicabilidad | AD20: Ponderación
A21: 1 | B21: El contratista mantiene actualizado el contenido de las carpetas A&SST exigidas | J21: X | N21: 4 | O21: ='SEMANA 1'!T21 -> 0.4 | P21: ='SEMANA 2'!T21 -> 0.4 | Q21: ='SEMANA 3'!T21 -> 0.2 | R21: ='SEMANA 4'!T21 -> 1 | S21: =AVERAGE(O21:R21) -> 0.5 | U21: =IF(SUM(N21:N25)<>U20,"Ajustar Ponderacion",IF(SUM(AD21:AD25)=0,"",IF(SUM(AC21:AC25)=U20,IF(SUM(N21:N25)=U20,SUM(AD21:AD25),"Ajustar ponderacion"),"Ajustar ponderacion"))) -> 18 | AC21: =IF(J21="x",N21) -> 4 | AD21: =AC21*S21 -> 2 | AF21: 0
A22: 2 | B22: Se cumple con el plan de acciones correctivas y/o preventivas a las observaciones en el ámbito A&SST hechas por la Interventoría en el desarrollo de las actividades del proyecto | J22: X | N22: 4 | O22: ='SEMANA 1'!T22 -> 1 | P22: ='SEMANA 2'!T22 -> 1 | Q22: ='SEMANA 3'!T22 -> 1 | R22: ='SEMANA 4'!T22 -> 1 | S22: =AVERAGE(O22:R22) -> 1 | AC22: =IF(J22="x",N22) -> 4 | AD22: =AC22*S22 -> 4 | AF22: 100
A23: 3 | B23: La brigada de orden, aseo y limpieza – BOAL está conformada y dotada de acuerdo a lo especificado en el pliego de condiciones y cumple sus funciones. | J23: X | N23: 4 | O23: ='SEMANA 1'!T23 -> 1 | P23: ='SEMANA 2'!T23 -> 1 | Q23: ='SEMANA 3'!T23 -> 1 | R23: ='SEMANA 4'!T23 -> 1 | S23: =AVERAGE(O23:R23) -> 1 | AC23: =IF(J23="x",N23) -> 4 | AD23: =AC23*S23 -> 4
A24: 4 | B24: Se entrega de manera oportuna de acuerdo a lo definido en los comités, todos los soportes de proveedores de materiales y sitio de disposición final de RCD producto de las actividades de obra. | J24: X | N24: 4 | O24: ='SEMANA 1'!T24 -> 1 | P24: ='SEMANA 2'!T24 -> 1 | Q24: ='SEMANA 3'!T24 -> 1 | R24: ='SEMANA 4'!T24 -> 1 | S24: =AVERAGE(O24:R24) -> 1 | AC24: =IF(J24="x",N24) -> 4 | AD24: =AC24*S24 -> 4
A25: 5 | B25: Se cumple con todos los procedimientos ofertados en el MAO aprobado | J25: X | N25: 4 | O25: ='SEMANA 1'!T25 -> 1 | P25: ='SEMANA 2'!T25 -> 1 | Q25: ='SEMANA 3'!T25 -> 1 | R25: ='SEMANA 4'!T25 -> 1 | S25: =AVERAGE(O25:R25) -> 1 | AC25: =IF(J25="x",N25) -> 4 | AD25: =AC25*S25 -> 4
A26: COMPONENTE B | U26: 50 | AC26: =IF(J26="x",N26) -> FALSE | AD26: =AC26*S26 -> 0
A27: 6 | B27: Hay escombros o materiales en espacio publico | J27: X | N27: 2.5 | O27: ='SEMANA 1'!T27 -> 1 | P27: ='SEMANA 2'!T27 -> 1 | Q27: ='SEMANA 3'!T27 -> 1 | R27: ='SEMANA 4'!T27 -> 0.6 | S27: =AVERAGE(O27:R27) -> 0.9 | U27: =IF(SUM(N27:N46)<>U26,"Ajuste ponderacion",IF(SUM(AD27:AD46)=0,"",IF(SUM(AC27:AC46)=U26,IF(SUM(N27:N46)=U26,SUM(AD27:AD46),"ajustar ponderacion"),"ajustar ponderacion"))) -> 49.375 | AC27: =IF(J27="x",N27) -> 2.5 | AD27: =AC27*S27 -> 2.25
A28: 7 | B28: Los materiales de la obra están cubiertos con lonas, plásticos o geotextil y acordonados | J28: X | N28: 2.5 | O28: ='SEMANA 1'!T28 -> 1 | P28: ='SEMANA 2'!T28 -> 1 | Q28: ='SEMANA 3'!T28 -> 1 | R28: ='SEMANA 4'!T28 -> 0.4 | S28: =AVERAGE(O28:R28) -> 0.85 | AC28: =IF(J28="x",N28) -> 2.5 | AD28: =AC28*S28 -> 2.125
A29: 8 | B29: Se implementan las medidas de manejo necesarias para impedir el aporte de sólidos o sustancias contaminantes al sistema de alcantarillado o cuerpos de agua. | J29: X | N29: 2.5 | O29: ='SEMANA 1'!T29 -> 1 | P29: ='SEMANA 2'!T29 -> 1 | Q29: ='SEMANA 3'!T29 -> 1 | R29: ='SEMANA 4'!T29 -> 1 | S29: =AVERAGE(O29:R29) -> 1 | AC29: =IF(J29="x",N29) -> 2.5 | AD29: =AC29*S29 -> 2.5
A30: 9 | B30: El campamento de obra se encuentra debidamente demarcado, señalizado, ordenado y aseado de acuerdo a lo ofertado en el MAO. | J30: X | N30: 2.5 | O30: ='SEMANA 1'!T30 -> 1 | P30: ='SEMANA 2'!T30 -> 1 | Q30: ='SEMANA 3'!T30 -> 1 | R30: ='SEMANA 4'!T30 -> 1 | S30: =AVERAGE(O30:R30) -> 1 | AC30: =IF(J30="x",N30) -> 2.5 | AD30: =AC30*S30 -> 2.5
A31: 10 | B31: Existe aislamiento del equipo y operario en uso de cortadora, para mitigar el material particulado | J31: X | N31: 2.5 | O31: ='SEMANA 1'!T31 -> 1 | P31: ='SEMANA 2'!T31 -> 1 | Q31: ='SEMANA 3'!T31 -> 1 | R31: ='SEMANA 4'!T31 -> 1 | S31: =AVERAGE(O31:R31) -> 1 | AC31: =IF(J31="x",N31) -> 2.5 | AD31: =AC31*S31 -> 2.5
A32: 11 | B32: Los materiales almacenados interfieren el trafico peatonal, vehicular y espacio publico | J32: X | N32: 2.5 | O32: ='SEMANA 1'!T32 -> 1 | P32: ='SEMANA 2'!T32 -> 1 | Q32: ='SEMANA 3'!T32 -> 1 | R32: ='SEMANA 4'!T32 -> 1 | S32: =AVERAGE(O32:R32) -> 1 | AC32: =IF(J32="x",N32) -> 2.5 | AD32: =AC32*S32 -> 2.5
A33: 12 | B33: Los vehículos para transporte de material no exceden su capacidad, están cubiertos los escombros | J33: X | N33: 2.5 | O33: ='SEMANA 1'!T33 -> 1 | P33: ='SEMANA 2'!T33 -> 1 | Q33: ='SEMANA 3'!T33 -> 1 | R33: ='SEMANA 4'!T33 -> 1 | S33: =AVERAGE(O33:R33) -> 1 | AC33: =IF(J33="x",N33) -> 2.5 | AD33: =AC33*S33 -> 2.5
A34: 13 | B34: Se garantiza la limpieza de las llantas de todos los vehículos que salen de la obra | J34: X | N34: 2.5 | O34: ='SEMANA 1'!T34 -> 1 | P34: ='SEMANA 2'!T34 -> 1 | Q34: ='SEMANA 3'!T34 -> 1 | R34: ='SEMANA 4'!T34 -> 1 | S34: =AVERAGE(O34:R34) -> 1 | AC34: =IF(J34="x",N34) -> 2.5 | AD34: =AC34*S34 -> 2.5
A35: 14 | B35: Se limpia el lugar donde se cargan las volquetas | J35: X | N35: 2.5 | O35: ='SEMANA 1'!T35 -> 1 | P35: ='SEMANA 2'!T35 -> 1 | Q35: ='SEMANA 3'!T35 -> 1 | R35: ='SEMANA 4'!T35 -> 1 | S35: =AVERAGE(O35:R35) -> 1 | AC35: =IF(J35="x",N35) -> 2.5 | AD35: =AC35*S35 -> 2.5
A36: 15 | B36: Se realiza la disposición final de los escombros en lugar autorizado | J36: X | N36: 2.5 | O36: ='SEMANA 1'!T36 -> 1 | P36: ='SEMANA 2'!T36 -> 1 | Q36: ='SEMANA 3'!T36 -> 1 | R36: ='SEMANA 4'!T36 -> 1 | S36: =AVERAGE(O36:R36) -> 1 | AC36: =IF(J36="x",N36) -> 2.5 | AD36: =AC36*S36 -> 2.5
A37: 16 | B37: Las canecas están marcadas para diferenciar el tipo de desecho y están pintadas con color adecuado | J37: X | N37: 2.5 | O37: ='SEMANA 1'!T37 -> 1 | P37: ='SEMANA 2'!T37 -> 1 | Q37: ='SEMANA 3'!T37 -> 1 | R37: ='SEMANA 4'!T37 -> 1 | S37: =AVERAGE(O37:R37) -> 1 | AC37: =IF(J37="x",N37) -> 2.5 | AD37: =AC37*S37 -> 2.5
A38: 17 | B38: Los desechos son evacuados máximo cada dos días por empresas publicas | J38: X | N38: 2.5 | O38: ='SEMANA 1'!T38 -> 1 | P38: ='SEMANA 2'!T38 -> 1 | Q38: ='SEMANA 3'!T38 -> 1 | R38: ='SEMANA 4'!T38 -> 1 | S38: =AVERAGE(O38:R38) -> 1 | AC38: =IF(J38="x",N38) -> 2.5 | AD38: =AC38*S38 -> 2.5
A39: 18 | B39: Se usan canecas para escurrir los tarros de aceites y filtros | J39: X | N39: 2.5 | O39: ='SEMANA 1'!T39 -> 1 | P39: ='SEMANA 2'!T39 -> 1 | Q39: ='SEMANA 3'!T39 -> 1 | R39: ='SEMANA 4'!T39 -> 1 | S39: =AVERAGE(O39:R39) -> 1 | AC39: =IF(J39="x",N39) -> 2.5 | AD39: =AC39*S39 -> 2.5
... A46: 25 | B46: Las unidades sanitarias se encuentran de acuerdo a lo especificado en los pliegos de condiciones y/o en la normativa vigente | J46: X | N46: 2.5 | O46: ='SEMANA 1'!T46 -> 1 | P46: ='SEMANA 2'!T46 -> 1 | Q46: ='SEMANA 3'!T46 -> 1 | R46: ='SEMANA 4'!T46 -> 1 | S46: =AVERAGE(O46:R46) -> 1 | AC46: =IF(J46="x",N46) -> 2.5 | AD46: =AC46*S46 -> 2.5
A47: COMPONENTE C | U47: 20 | AC47: =IF(J47="x",N47) -> FALSE | AD47: =AC47*S47 -> 0
A48: 26 | B48: Las zonas verdes en el área de intervención de la obra se encuentran libres de materiales de construcción, a menos que se cuente con la autorización de la interventoría y/o la Autoridad Competente para uso temporal. Las zonas verdes usadas temporalmente deben quedan en condiciones iguales o mejores a las presentes antes de la afectación. | J48: X | N48: 4 | O48: ='SEMANA 1'!T48 -> 1 | P48: ='SEMANA 2'!O48 -> 1 | Q48: ='SEMANA 3'!T48 -> 1 | R48: ='SEMANA 4'!S48 -> 1 | S48: =AVERAGE(O48:R48) -> 1 | U48: =IF(SUM(N48:N52)<>U47,"AJUSTAR PONDERACION",IF(SUM(AD48:AD52)=0,"",IF(SUM(AC48:AC52)=U47,IF(SUM(N48:N52)=U47,SUM(AD48:AD52),"Ajustar ponderacion"),"Ajustar ponderacion"))) -> 20 | AC48: =IF(J48="x",N48) -> 4 | AD48: =AC48*S48 -> 4
A49: 27 | B49: Sí existen individuos arbóreos en el área de influencia directa de la obra, éstos se encuentran debidamente protegidos según las especificaciones que al respecto se incluyen en el estipulado en el apéndice A&SST y sin afectación alguna por las actividades o acciones de obra. | J49: X | N49: 4 | O49: ='SEMANA 1'!T49 -> 1 | P49: ='SEMANA 2'!O49 -> 1 | Q49: ='SEMANA 3'!T49 -> 1 | R49: ='SEMANA 4'!S49 -> 1 | S49: =AVERAGE(O49:R49) -> 1 | AC49: =IF(J49="x",N49) -> 4 | AD49: =AC49*S49 -> 4
A50: 28 | B50: Se realiza la ejecución de tratamientos silviculturales y el procedimiento de avifauna según lo estipulado por el Manual de Silvicultura Urbana del JBB y en cumplimiento de la Resolución de aprobación emitida por la AAC | J50: X | N50: 4 | O50: 1 | P50: 1 | Q50: 1 | R50: 1 | S50: =AVERAGE(O50:R50) -> 1 | AC50: =IF(J50="x",N50) -> 4 | AD50: =AC50*S50 -> 4
A51: 29 | B51: Se realiza el seguimiento y mantenimiento periódico de los individuos vegetales del área de influencia del contrato. | J51: X | N51: 4 | O51: ='SEMANA 1'!T51 -> 1 | P51: ='SEMANA 2'!O51 -> 1 | Q51: ='SEMANA 3'!T51 -> 1 | R51: ='SEMANA 4'!S51 -> 1 | S51: =AVERAGE(O51:R51) -> 1 | AC51: =IF(J51="x",N51) -> 4 | AD51: =AC51*S51 -> 4
A52: 27 | B52: Se cuenta con personal de medio ambiente encargado de realizar actividades en este tema | J52: X | N52: 4 | O52: ='SEMANA 1'!T52 -> 1 | P52: ='SEMANA 2'!O52 -> 1 | Q52: ='SEMANA 3'!T52 -> 1 | R52: ='SEMANA 4'!S52 -> 1 | S52: =AVERAGE(O52:R52) -> 1 | AC52: =IF(J52="x",N52) -> 4 | AD52: =AC52*S52 -> 4
...
